2017-02-03 21:41:06,612 DEBUG    root            Loaded Command Group: ['gcloud', 'projects']
2017-02-03 21:41:06,698 DEBUG    root            Loaded Command Group: ['gcloud', 'projects', 'describe']
2017-02-03 21:41:06,700 DEBUG    root            Running gcloud.projects.describe with Namespace(__calliope_internal_deepest_parser=ArgumentParser(prog='gcloud.projects.describe', usage=None, description='Shows metadata for a project given a valid project ID.\n\nThis command can fail for the following reasons:\n* The project specified does not exist.\n* The active account does not have permission to access the given project.\n\n## EXAMPLES\n\nThe following command prints metadata for a project with the ID\n`example-foo-bar-1`:\n\n  $ {command} example-foo-bar-1', version=None, formatter_class=<class 'argparse.HelpFormatter'>, conflict_handler='error', add_help=False), account=None, authority_selector=None, authorization_token_file=None, calliope_command=<googlecloudsdk.calliope.backend.Command object at 0x7f0d9394ba50>, command_path=['gcloud', 'projects', 'describe'], configuration=None, credential_file_override=None, document=None, flatten=None, format='value(projectNumber)', h=None, help=None, http_timeout=None, id='pro-bliss-156604', log_http=None, project=None, quiet=None, trace_email=None, trace_log=None, trace_token=None, user_output_enabled=None, verbosity='warning', version=None).
2017-02-03 21:41:06,809 DEBUG    root            HttpError in projects API call.
Traceback (most recent call last):
  File "/tools/google-cloud-sdk/lib/googlecloudsdk/api_lib/cloudresourcemanager/projects_api.py", line 53, in Get
    projectId=project_ref.projectId))
  File "/tools/google-cloud-sdk/lib/googlecloudsdk/third_party/apis/cloudresourcemanager/v1/cloudresourcemanager_v1_client.py", line 334, in Get
    config, request, global_params=global_params)
  File "/tools/google-cloud-sdk/lib/third_party/apitools/base/py/base_api.py", line 723, in _RunMethod
    return self.ProcessHttpResponse(method_config, http_response, request)
  File "/tools/google-cloud-sdk/lib/third_party/apitools/base/py/base_api.py", line 729, in ProcessHttpResponse
    self.__ProcessHttpResponse(method_config, http_response, request))
  File "/tools/google-cloud-sdk/lib/third_party/apitools/base/py/base_api.py", line 599, in __ProcessHttpResponse
    http_response.request_url, method_config, request)
HttpError: HttpError accessing <https://cloudresourcemanager.googleapis.com/v1/projects/pro-bliss-156604?alt=json>: response: <{'status': '403', 'content-length': '812', 'x-xss-protection': '1; mode=block', 'x-content-type-options': 'nosniff', 'transfer-encoding': 'chunked', 'vary': 'Origin, X-Origin, Referer', 'server': 'ESF', '-content-encoding': 'gzip', 'cache-control': 'private', 'date': 'Fri, 03 Feb 2017 21:41:06 GMT', 'x-frame-options': 'SAMEORIGIN', 'alt-svc': 'quic=":443"; ma=2592000; v="35,34"', 'content-type': 'application/json; charset=UTF-8'}>, content <{
  "error": {
    "code": 403,
    "message": "Google Cloud Resource Manager API has not been used in project pro-bliss-156604 before or it is disabled. Enable it by visiting https://console.developers.google.com/apis/api/cloudresourcemanager.googleapis.com/overview?project=pro-bliss-156604 then retry. If you enabled this API recently, wait a few minutes for the action to propagate to our systems and retry.",
    "status": "PERMISSION_DENIED",
    "details": [
      {
        "@type": "type.googleapis.com/google.rpc.Help",
        "links": [
          {
            "description": "Google developers console API activation",
            "url": "https://console.developers.google.com/apis/api/cloudresourcemanager.googleapis.com/overview?project=pro-bliss-156604"
          }
        ]
      }
    ]
  }
}
>
2017-02-03 21:41:06,810 DEBUG    root            (gcloud.projects.describe) Project [pro-bliss-156604] does not exist, or you do not have permission to access it.
Traceback (most recent call last):
  File "/tools/google-cloud-sdk/lib/googlecloudsdk/calliope/cli.py", line 742, in Execute
    resources = args.calliope_command.Run(cli=self, args=args)
  File "/tools/google-cloud-sdk/lib/googlecloudsdk/calliope/backend.py", line 1710, in Run
    resources = command_instance.Run(args)
  File "/tools/google-cloud-sdk/lib/surface/projects/describe.py", line 52, in Run
    return projects_api.Get(project_ref)
  File "/tools/google-cloud-sdk/lib/googlecloudsdk/api_lib/cloudresourcemanager/projects_api.py", line 55, in Get
    raise projects_util.ConvertHttpError(error)
ProjectAccessError: Project [pro-bliss-156604] does not exist, or you do not have permission to access it.
2017-02-03 21:41:06,811 ERROR    root            (gcloud.projects.describe) Project [pro-bliss-156604] does not exist, or you do not have permission to access it.
